<mujoco model="inverted_pendulum">
    <!-- Background texture -->
    <asset>
        <texture name="grid" type="2d" builtin="checker" rgb1=".1 .2 .3"
        rgb2=".2 .3 .4" width="100" height="100"/>
        <material name="grid" texture="grid" texrepeat="8 8" reflectance=".2"/>
    </asset>

    

    <worldbody>
        <!-- Place background -->
        <geom size="2 2 .01" type="plane" material="grid"/>
        <!-- Static light -->
        <light pos="0 0 3" dir="0 0 -1" diffuse=".8 .8 .8" specular=".3 .3 .3"/>

        <!-- Cart -->
        <body name="cart" pos="0 0 1">
            <!-- Sliding joint only in the x direction -->
            <joint name="cart_slide" type="slide" axis="1 0 0"/>
            <!-- Size is half size -->
            <geom name="cart_geom" type="box" size="0.2 0.1 0.1" rgba="0.2 0.6 0.8 0.2"/>
            <inertial mass="10" diaginertia="1e-5 1e-5 1e-5" pos="0 0 0"/>

            <!-- Weightless pendulum -->
            <body name="pendulum_stick" pos="0 0 0.1">
                <joint name="hinge" type="hinge" axis="0 1 0" pos="0 0 0"/>
                <geom name="pendulum_stick_geom" type="capsule" fromto="0 0 0 0 0 0.8" size="0.025"/>
                <inertial mass="0.0001" diaginertia="1e-5 1e-5 1e-5"  pos="0 0 0"/>
                
                <!-- Mass on the end of the pendulum -->
                <body name="pendulum" pos="0 0 0.8">
                    <geom name="pendulum_geom" type="sphere" size="0.1"/>
                    <inertial mass="3" diaginertia="1e-5 1e-5 1e-5" pos="0 0 0"/>
                </body>
            </body>
        </body>

    </worldbody>
    
    <!-- Force actuator on the cart -->
    <actuator>
        <general joint="cart_slide" ctrllimited="true" ctrlrange="-50 50"/>
    </actuator>

</mujoco>
