<mujoco model="iiwa14">
  <compiler angle="radian" meshdir="assets" autolimits="true"/>

  <option integrator="implicitfast"/>

  <default>
    <default class="iiwa">
      <material specular="0.5" shininess="0.25"/>
      <joint axis="0 0 1"/>
      <default class="joint1">
        <joint range="-2.96706 2.96706"/>
        <default class="joint2">
          <joint range="-2.0944 2.0944"/>
        </default>
      </default>
      <default class="joint3">
        <joint range="-3.05433 3.05433"/>
      </default>
      <default class="visual">
        <geom type="mesh" contype="0" conaffinity="0" group="2" material="gray"/>
      </default>
      <default class="collision">
        <geom group="3"/>
      </default>
      <site size="0.001" rgba="1 0 0 1" group="4"/>
    </default>
  </default>

  <asset>
    <material class="iiwa" name="gray" rgba="0.4 0.4 0.4 1"/>
    <material class="iiwa" name="light_gray" rgba="0.6 0.6 0.6 1"/>
    <material class="iiwa" name="black" rgba="0 0 0 1"/>
    <material class="iiwa" name="orange" rgba="1 0.423529 0.0392157 1"/>

    <mesh file="link_0.obj"/>
    <mesh file="link_1.obj"/>
    <mesh file="link_2_orange.obj"/>
    <mesh file="link_2_grey.obj"/>
    <mesh file="link_3.obj"/>
    <mesh file="band.obj"/>
    <mesh file="kuka.obj"/>
    <mesh file="link_4_orange.obj"/>
    <mesh file="link_4_grey.obj"/>
    <mesh file="link_5.obj"/>
    <mesh file="link_6_orange.obj"/>
    <mesh file="link_6_grey.obj"/>
    <mesh file="link_7.obj"/>
  </asset>

  <worldbody>
    <light name="top" pos="0 0 2" mode="trackcom"/>
    <body name="base" childclass="iiwa">
      <inertial mass="5" pos="-0.1 0 0.07" diaginertia="0.05 0.06 0.03"/>
      <geom class="visual" mesh="link_0"/>
      <body name="link1" pos="0 0 0.1575">
        <inertial mass="5.76" pos="0 -0.03 0.12" diaginertia="0.0333 0.033 0.0123"/>
        <joint name="joint1" class="joint1"/>
        <geom class="visual" mesh="link_1"/>
        <geom class="collision" name="collision_capsule1" type="capsule" fromto="0 0 -0.15 0 0 0.15" size="0.15" rgba="0.0 0.0 1.0 0.2"/>
        <body name="link2" pos="0 0 0.2025" quat="0 0 1 1">
          <inertial mass="6.35" pos="0.0003 0.059 0.042" diaginertia="0.0305 0.0304 0.011" quat="0 0 1 1"/>
          <joint name="joint2" class="joint2"/>
          <geom class="visual" material="orange" mesh="link_2_orange"/>
          <geom class="visual" mesh="link_2_grey"/>
          <!-- <geom class="collision" name="collision_capsule2" type="capsule" fromto="0 0 0 0 0 0.028" size="0.12" rgba="0.0 1.0 0.0 0.2"/> -->
          <body name="link3" pos="0 0.2045 0" quat="0 0 1 1">
            <inertial mass="3.5" pos="0 0.03 0.13" diaginertia="0.025 0.0238 0.0076"/>
            <joint name="joint3" class="joint1"/>
            <geom class="visual" mesh="link_3"/>
            <geom class="visual" material="light_gray" mesh="band"/>
            <geom class="visual" material="black" mesh="kuka"/>
            <geom class="collision" name="collision_capsule3" type="capsule" fromto="0 0 -0.2 0 0 0.2" size="0.12" rgba="1.0 0.0 0.0 0.2"/>
            <body name="link4" pos="0 0 0.2155" quat="1 1 0 0">
              <inertial mass="3.5" pos="0 0.067 0.034" diaginertia="0.017 0.0164 0.006" quat="1 1 0 0"/>
              <joint name="joint4" class="joint2"/>
              <geom class="visual" material="orange" mesh="link_4_orange"/>
              <geom class="visual" mesh="link_4_grey"/>
              <!-- <geom class="collision" name="collision_capsule4" type="capsule" fromto="0 0 0 0 0 0.028" size="0.12" rgba="0.0 0.0 1.0 0.2"/> -->
              <body name="link5" pos="0 0.1845 0" quat="0 0 1 1">
                <inertial mass="3.5" pos="0.0001 0.021 0.076" diaginertia="0.01 0.0087 0.00449"/>
                <joint name="joint5" class="joint1"/>
                <geom class="visual" mesh="link_5"/>
                <geom class="visual" material="light_gray" mesh="band"/>
                <geom class="visual" material="black" mesh="kuka"/>
                <geom class="collision" name="collision_capsule5" type="capsule" fromto="0 0 -0.16 0 0 0.2" size="0.10" rgba="0.0 1.0 0.0 0.2"/>
                <body name="link6" pos="0 0 0.2155" quat="1 1 0 0">
                  <inertial mass="1.8" pos="0 0.0006 0.0004" diaginertia="0.0049 0.0047 0.0036" quat="1 1 0 0"/>
                  <joint name="joint6" class="joint2"/>
                  <geom class="visual" material="orange" mesh="link_6_orange"/>
                  <geom class="visual" mesh="link_6_grey"/>
                  <body name="link7" pos="0 0.081 0" quat="0 0 1 1">
                    <inertial mass="1.2" pos="0 0 0.02" diaginertia="0.001 0.001 0.001"/>
                    <joint name="joint7" class="joint3"/>
                    <geom class="visual" mesh="link_7"/>
                    <geom class="collision" name="collision_capsule7" type="capsule" fromto="0 0 0.0 0 0 0.005" size="0.06" rgba="0.0 0.0 1.0 0.2"/>
                    <!-- <geom class="collision" size="0.06" pos="0 0 0.001"/> -->
                    <site pos="0 0 0.045" name="attachment_site"/>
                  </body>
                </body>
              </body>
            </body>
          </body>
        </body>
      </body>
    </body>
  </worldbody>

  <contact>
    <exclude body1="base" body2="link1"/>
    <exclude body1="base" body2="link2"/>
    <exclude body1="base" body2="link3"/>
    <exclude body1="link1" body2="link3"/>
    <exclude body1="link3" body2="link5"/>
    <exclude body1="link4" body2="link7"/>
    <exclude body1="link5" body2="link7"/>
  </contact>

  <actuator>
    <general name="actuator1" joint="joint1" class="joint1" ctrlrange="-320 320"/>
    <general name="actuator2" joint="joint2" class="joint2" ctrlrange="-320 320"/>
    <general name="actuator3" joint="joint3" class="joint1" ctrlrange="-176 176"/>
    <general name="actuator4" joint="joint4" class="joint2" ctrlrange="-176 176"/>
    <general name="actuator5" joint="joint5" class="joint1" ctrlrange="-110 110"/>
    <general name="actuator6" joint="joint6" class="joint2" ctrlrange="-40 40"/>
    <general name="actuator7" joint="joint7" class="joint3" ctrlrange="-40 40"/>
  </actuator>

  <keyframe>
    <key name="home" qpos="0 0.785398 0 -1.5708 0 0 0" ctrl="0 0.785398 0 -1.5708 0 0 0"/>
  </keyframe>
</mujoco>
